ERROR:root:Traceback (most recent call last):
  File "H:/Python(Âí¸ç2015)/PPT/MagePython/Selenium_Test/grafana_monitor.py", line 30, in work
    browser.find_element_by_link_text("dashboard/db/interface_49")
  File "C:\Program Files (x86)\Python35-32\lib\site-packages\selenium\webdriver\remote\webdriver.py", line 317, in find_element_by_link_text
    return self.find_element(by=By.LINK_TEXT, value=link_text)
  File "C:\Program Files (x86)\Python35-32\lib\site-packages\selenium\webdriver\remote\webdriver.py", line 752, in find_element
    'value': value})['value']
  File "C:\Program Files (x86)\Python35-32\lib\site-packages\selenium\webdriver\remote\webdriver.py", line 236, in execute
    self.error_handler.check_response(response)
  File "C:\Program Files (x86)\Python35-32\lib\site-packages\selenium\webdriver\remote\errorhandler.py", line 192, in check_response
    raise exception_class(message, screen, stacktrace)
selenium.common.exceptions.NoSuchElementException: Message: Unable to locate element: dashboard/db/interface_49


